<?xml version="1.0" ?>
<robot name="walker2d">
    <!-- Torso -->
    <link name="torso">
        <inertial>
            <origin xyz="0 0 0" rpy="0 0 0" />
            <mass value="5.0" />
            <inertia ixx="0.1" iyy="0.1" izz="0.1" ixy="0" ixz="0" iyz="0" />
        </inertial>
        <collision>
            <origin xyz="0 0 0" rpy="0 0 0" />
            <geometry>
                <cylinder length="0.225" radius="0.05" />
            </geometry>
        </collision>
    </link>

    <!-- Right Thigh -->
    <link name="thigh">
        <inertial>
            <origin xyz="0 0 -0.2" rpy="0 0 0" />
            <mass value="2.0" />
            <inertia ixx="0.05" iyy="0.05" izz="0.01" ixy="0" ixz="0" iyz="0" />
        </inertial>
        <collision>
            <origin xyz="0 0 -0.2" rpy="0 0 0" />
            <geometry>
                <cylinder length="0.275" radius="0.05" />
            </geometry>
        </collision>
    </link>

    <!-- Right Leg -->
    <link name="leg">
        <inertial>
            <origin xyz="0 0 -0.25" rpy="0 0 0" />
            <mass value="1.5" />
            <inertia ixx="0.03" iyy="0.03" izz="0.005" ixy="0" ixz="0" iyz="0" />
        </inertial>
        <collision>
            <origin xyz="0 0 -0.25" rpy="0 0 0" />
            <geometry>
                <cylinder length="0.250" radius="0.04" />
            </geometry>
        </collision>
    </link>

    <!-- Right Foot -->
    <link name="foot">
        <inertial>
            <origin xyz="-0.1 0 0.05" rpy="0 -1.57 0" />
            <mass value="1.0" />
            <inertia ixx="0.02" iyy="0.01" izz="0.01" ixy="0" ixz="0" iyz="0" />
        </inertial>
        <collision>
            <origin xyz="-0.1 0 0.05" rpy="0 -1.57 0" />
            <geometry>
                <cylinder length="0.100" radius="0.06" />
            </geometry>
        </collision>
    </link>

    <!-- Left Thigh -->
    <link name="thigh_left">
        <inertial>
            <origin xyz="0 0 -0.2" rpy="0 0 0" />
            <mass value="2.0" />
            <inertia ixx="0.05" iyy="0.05" izz="0.01" ixy="0" ixz="0" iyz="0" />
        </inertial>
        <collision>
            <origin xyz="0 0 -0.2" rpy="0 0 0" />
            <geometry>
                <cylinder length="0.275" radius="0.05" />
            </geometry>
        </collision>
    </link>

    <!-- Left Leg -->
    <link name="leg_left">
        <inertial>
            <origin xyz="0 0 -0.25" rpy="0 0 0" />
            <mass value="1.5" />
            <inertia ixx="0.03" iyy="0.03" izz="0.005" ixy="0" ixz="0" iyz="0" />
        </inertial>
        <collision>
            <origin xyz="0 0 -0.25" rpy="0 0 0" />
            <geometry>
                <cylinder length="0.250" radius="0.04" />
            </geometry>
        </collision>
    </link>

    <!-- Left Foot -->
    <link name="foot_left">
        <inertial>
            <origin xyz="-0.1 0 0.05" rpy="0 -1.57 0" />
            <mass value="1.0" />
            <inertia ixx="0.02" iyy="0.01" izz="0.01" ixy="0" ixz="0" iyz="0" />
        </inertial>
        <collision>
            <origin xyz="-0.1 0 0.05" rpy="0 -1.57 0" />
            <geometry>
                <cylinder length="0.100" radius="0.06" />
            </geometry>
        </collision>
    </link>

    <!-- Root joint for controlling position and orientation of the robot -->
    <joint name="root_xyz" type="floating">
        <origin xyz="0 0 0" rpy="0 0 0" />
        <parent link="world" />
        <child link="torso" />
        <axis xyz="0 0 1" />
        <limit lower="-10" upper="10" effort="100" velocity="1.0" />
    </joint>

    <!-- Joints -->
    <joint name="hip_right" type="revolute">
        <origin xyz="0 0 0" rpy="0 0 0" />
        <parent link="torso" />
        <child link="thigh" />
        <axis xyz="0 1 0" />
        <limit effort="50" lower="-1.57" upper="1.57" velocity="1.0" />
    </joint>

    <joint name="knee_right" type="revolute">
        <origin xyz="0 0 -0.4" rpy="0 0 0" />
        <parent link="thigh" />
        <child link="leg" />
        <axis xyz="0 1 0" />
        <limit effort="50" lower="0" upper="1.57" velocity="1.0" />
    </joint>

    <joint name="ankle_right" type="revolute">
        <origin xyz="0 0 -0.5" rpy="0 0 0" />
        <parent link="leg" />
        <child link="foot" />
        <axis xyz="1 0 0" />
        <limit effort="30" lower="-0.5" upper="0.5" velocity="1.0" />
    </joint>

    <!-- Left Joints -->
    <joint name="hip_left" type="revolute">
        <origin xyz="0 0 0" rpy="0 0 0" />
        <parent link="torso" />
        <child link="thigh_left" />
        <axis xyz="0 1 0" />
        <limit effort="50" lower="-1.57" upper="1.57" velocity="1.0" />
    </joint>

    <joint name="knee_left" type="revolute">
        <origin xyz="0 0 -0.4" rpy="0 0 0" />
        <parent link="thigh_left" />
        <child link="leg_left" />
        <axis xyz="0 1 0" />
        <limit effort="50" lower="0" upper="1.57" velocity="1.0" />
    </joint>

    <joint name="ankle_left" type="revolute">
        <origin xyz="0 0 -0.5" rpy="0 0 0" />
        <parent link="leg_left" />
        <child link="foot_left" />
        <axis xyz="1 0 0" />
        <limit effort="30" lower="-0.5" upper="0.5" velocity="1.0" />
    </joint>
</robot>
