<mujoco model="ant">
  <compiler angle="degree" coordinate="local" inertiafromgeom="true" />
  <option integrator="RK4" timestep="0.01" />
  <custom>
    <numeric data="0.0 0.0 0.55 1.0 0.0 0.0 0.0 0.0 1.0 0.0 -1.0 0.0 -1.0 0.0 1.0" name="init_qpos" />
  </custom>
  <default>
    <joint armature="1" damping="1" limited="true" />
    <geom conaffinity="0" condim="3" density="5.0" friction="1 0.5 0.5" margin="0.01" rgba="0.8 0.6 0.4 1" />
  </default>
  <asset>
    <texture builtin="gradient" height="100" rgb1="1 1 1" rgb2="0 0 0" type="skybox" width="100" />
    <texture builtin="flat" height="1278" mark="cross" markrgb="1 1 1" name="texgeom" random="0.01" rgb1="0.8 0.6 0.4" rgb2="0.8 0.6 0.4" type="cube" width="127" />
    <texture builtin="checker" height="100" name="texplane" rgb1="0 0 0" rgb2="0.8 0.8 0.8" type="2d" width="100" />
    <material name="MatPlane" reflectance="0.5" shininess="1" specular="1" texrepeat="60 60" texture="texplane" />
    <material name="geom" texture="texgeom" texuniform="true" />
  </asset>
  <worldbody>
    <light cutoff="100" diffuse="1 1 1" dir="-0 0 -1.3" directional="true" exponent="1" pos="0 0 1.3" specular=".1 .1 .1" />
    <geom conaffinity="1" condim="3" material="MatPlane" name="floor" pos="0 0 0" rgba="0.8 0.9 0.8 1" size="40 40 40" type="plane" />
    <body name="torso" pos="0 0 0.75">
      <camera name="track" mode="trackcom" pos="0 -11 5" xyaxes="1 0 0 0 0.5 1" />
      <geom name="torso_geom" pos="0 0 0" size="0.0366084910929203" type="sphere" />
      <joint armature="0" damping="0" limited="false" margin="0.01" name="root" pos="0 0 0" type="free" />
      <body name="front_left_leg" pos="0 0 0">
        <geom fromto="0 0 0 0.33045995235443115 0.33045995235443115 0" name="aux_1_geom" size="0.03484195098280907" type="capsule" />
        <body name="aux_1" pos="0.33045995235443115 0.33045995235443115 0">
          <joint axis="0 0 1" name="hip_1" pos="0.0 0.0 0.0" range="-30 30" type="hinge" />
          <geom fromto="0 0 0 0.6438761353492737 0.6438761353492737 0" name="left_leg_geom" size="0.01994301751255989" type="capsule" />
          <body name="left_leg_geom_aux" pos="0.6438761353492737 0.6438761353492737 0">
            <joint axis="-1 1 0" name="ankle_1" pos="0.0 0.0 0.0" range="30 70" type="hinge" />
            <geom fromto="0 0 0 0.19997650384902954 0.19997650384902954 0" name="left_ankle_geom" size="0.04806172475218773" type="capsule" />
          </body>
        </body>
      </body>
      <body name="front_right_leg" pos="0 0 0">
        <geom fromto="0 0 0 -0.8062549233436584 0.8062549233436584 0" name="aux_2_geom" size="0.023243088275194168" type="capsule" />
        <body name="aux_2" pos="-0.8062549233436584 0.8062549233436584 0">
          <joint axis="0 0 1" name="hip_2" pos="0.0 0.0 0.0" range="-30 30" type="hinge" />
          <geom fromto="0 0 0 -0.12055444717407227 0.12055444717407227 0" name="right_leg_geom" size="0.043401993811130524" type="capsule" />
          <body name="right_leg_geom_aux" pos="-0.12055444717407227 0.12055444717407227 0">
            <joint axis="1 1 0" name="ankle_2" pos="0.0 0.0 0.0" range="-70 -30" type="hinge" />
            <geom fromto="0 0 0 -0.8124803304672241 0.8124803304672241 0" name="right_ankle_geom" size="0.03814727067947388" type="capsule" />
          </body>
        </body>
      </body>
      <body name="back_leg" pos="0 0 0">
        <geom fromto="0 0 0 -0.3316698968410492 -0.3316698968410492 0" name="aux_3_geom" size="0.02346339076757431" type="capsule" />
        <body name="aux_3" pos="-0.3316698968410492 -0.3316698968410492 0">
          <joint axis="0 0 1" name="hip_3" pos="0.0 0.0 0.0" range="-30 30" type="hinge" />
          <geom fromto="0 0 0 -0.3324373960494995 -0.3324373960494995 0" name="back_leg_geom" size="0.023299219086766243" type="capsule" />
          <body name="back_leg_geom_aux" pos="-0.3324373960494995 -0.3324373960494995 0">
            <joint axis="-1 1 0" name="ankle_3" pos="0.0 0.0 0.0" range="-70 -30" type="hinge" />
            <geom fromto="0 0 0 -0.9352032542228699 -0.9352032542228699 0" name="third_ankle_geom" size="0.03165002539753914" type="capsule" />
          </body>
        </body>
      </body>
      <body name="right_back_leg" pos="0 0 0">
        <geom fromto="0 0 0 0.47725704312324524 -0.47725704312324524 0" name="aux_4_geom" size="0.035618800669908524" type="capsule" />
        <body name="aux_4" pos="0.47725704312324524 -0.47725704312324524 0">
          <joint axis="0 0 1" name="hip_4" pos="0.0 0.0 0.0" range="-30 30" type="hinge" />
          <geom fromto="0 0 0 0.5278708338737488 -0.5278708338737488 0" name="rightback_leg_geom" size="0.018681909888982773" type="capsule" />
          <body name="rightback_leg_geom_aux" pos="0.5278708338737488 -0.5278708338737488 0">
            <joint axis="1 1 0" name="ankle_4" pos="0.0 0.0 0.0" range="30 70" type="hinge" />
            <geom fromto="0 0 0 0.5899307727813721 -0.5899307727813721 0" name="fourth_ankle_geom" size="0.036796241998672485" type="capsule" />
          </body>
        </body>
      </body>
    </body>
  </worldbody>
  <actuator>
    <motor ctrllimited="true" ctrlrange="-1.0 1.0" joint="hip_4" gear="150" />
    <motor ctrllimited="true" ctrlrange="-1.0 1.0" joint="ankle_4" gear="150" />
    <motor ctrllimited="true" ctrlrange="-1.0 1.0" joint="hip_1" gear="150" />
    <motor ctrllimited="true" ctrlrange="-1.0 1.0" joint="ankle_1" gear="150" />
    <motor ctrllimited="true" ctrlrange="-1.0 1.0" joint="hip_2" gear="150" />
    <motor ctrllimited="true" ctrlrange="-1.0 1.0" joint="ankle_2" gear="150" />
    <motor ctrllimited="true" ctrlrange="-1.0 1.0" joint="hip_3" gear="150" />
    <motor ctrllimited="true" ctrlrange="-1.0 1.0" joint="ankle_3" gear="150" />
  </actuator>
</mujoco>