<mujoco model="walker2d">
  <compiler angle="degree" inertiafromgeom="true" />
  <default>
    <joint armature="0.01" damping=".1" limited="true" />
    <geom conaffinity="0" condim="3" contype="1" density="1000" friction=".7 .1 .1" rgba="0.8 0.6 .4 1" />
  </default>
  <option integrator="RK4" timestep="0.002" />
  <worldbody>
    <light cutoff="100" diffuse="1 1 1" dir="-0 0 -1.3" directional="true" exponent="1" pos="0 0 1.3" specular=".1 .1 .1" />
    <geom conaffinity="1" condim="3" name="floor" pos="0 0 0" rgba="0.8 0.9 0.8 1" size="40 40 40" type="plane" material="MatPlane" />
    <body name="torso" pos="0 0 1.5739269614219666">
      <camera name="track" mode="trackcom" pos="0 -5 -1.25" xyaxes="1 0 0 0 0 1" />
      <joint armature="0" axis="1 0 0" damping="0" limited="false" name="rootx" pos="0 0 -1.25" stiffness="0" type="slide" />
      <joint armature="0" axis="0 0 1" damping="0" limited="false" name="rootz" pos="0 0 -1.25" ref="1.25" stiffness="0" type="slide" />
      <joint armature="0" axis="0 1 0" damping="0" limited="false" name="rooty" pos="0 0 0" stiffness="0" type="hinge" />
      <geom friction="0.9" name="torso_geom" size="0.014151565730571747 0.2675457000732422" type="capsule" />
      <body name="thigh" pos="0 0 -0.2675457000732422">
        <joint axis="0 -1 0" name="thigh_joint" pos="0 0 0" range="-150 0" type="hinge" />
        <site name="torso_thigh_site" pos="0 0 0" size="0.01" type="sphere" rgba="1 0 0 0.5" />
        <geom friction="0.9" pos="0 0 -0.19204804301261902" name="thigh_geom" size="0.04230540618300438 0.19204804301261902" type="capsule" />
        <body name="leg" pos="0 0 -0.7952386736869812">
          <joint axis="0 -1 0" name="leg_joint" pos="0 0 0.41114258766174316" range="-150 0" type="hinge" />
          <site name="thigh_leg_site" pos="0 0 0.25" size="0.01" type="sphere" rgba="1 0 0 0.5" />
          <geom friction="0.9" name="leg_geom" size="0.04588206112384796 0.41114258766174316" type="capsule" />
          <body name="foot" pos="0.7068576216697693 0 -0.5111425876617431">
            <joint axis="0 -1 0" name="foot_joint" pos="-0.7068576216697693 0 0.1" range="-45 45" type="hinge" />
            <site name="leg_foot_site" pos="-0.2 0 0.1" size="0.01" type="sphere" rgba="1 0 0 0.5" />
            <geom friction="0.9" pos="-0.35342881083488464 0 0.1" quat="0.70710678118654757 0 -0.70710678118654746 0" name="foot_geom" size="0.02198690176010132 0.35342881083488464" type="capsule" />
          </body>
        </body>
      </body>
      
      <body name="thigh_left" pos="0 0 -0.2675457000732422">
        <joint axis="0 -1 0" name="thigh_left_joint" pos="0 0 0" range="-150 0" type="hinge" />
        <site name="torso_thigh_left_site" pos="0 0 0" size="0.01" type="sphere" rgba="1 0 0 0.5" />
        <geom friction="0.9" name="thigh_left_geom" rgba=".7 .3 .6 1" size="0.04230540618300438 0.19204804301261902" pos="0 0 -0.19204804301261902" type="capsule" />
        <body name="leg_left" pos="0 0 -0.7952386736869812">
          <joint axis="0 -1 0" name="leg_left_joint" pos="0 0 0.41114258766174316" range="-150 0" type="hinge" />
          <site name="thigh_leg_left_site" pos="0 0 0.25" size="0.01" type="sphere" rgba="1 0 0 0.5" />
          <geom friction="0.9" name="leg_left_geom" rgba=".7 .3 .6 1" size="0.04588206112384796 0.41114258766174316" type="capsule" />
          <body name="foot_left" pos="0.7068576216697693 0 -0.5111425876617431">
            <joint axis="0 -1 0" name="foot_left_joint" pos="-0.7068576216697693 0 0.1" range="-45 45" type="hinge" />
            <site name="leg_foot_left_site" pos="-0.2 0 0.1" size="0.01" type="sphere" rgba="1 0 0 0.5" />
            <geom friction="1.9" name="foot_left_geom" rgba=".7 .3 .6 1" size="0.02198690176010132 0.35342881083488464" pos="-0.35342881083488464 0 0.1" type="capsule" quat="0.70710678118654757 0 -0.70710678118654746 0" />
          </body>
        </body>
      </body>
    </body>
  </worldbody>
  <actuator>
    
    <motor ctrllimited="true" ctrlrange="-1.0 1.0" gear="61.105330520867305" joint="thigh_joint" />
    <motor ctrllimited="true" ctrlrange="-1.0 1.0" gear="216.38059559936488" joint="leg_joint" />
    <motor ctrllimited="true" ctrlrange="-1.0 1.0" gear="47.459976690067414" joint="foot_joint" />
    <motor ctrllimited="true" ctrlrange="-1.0 1.0" gear="61.105330520867305" joint="thigh_left_joint" />
    <motor ctrllimited="true" ctrlrange="-1.0 1.0" gear="216.38059559936488" joint="leg_left_joint" />
    <motor ctrllimited="true" ctrlrange="-1.0 1.0" gear="47.459976690067414" joint="foot_left_joint" />
    
  </actuator>
    <asset>
        <texture type="skybox" builtin="gradient" rgb1=".4 .5 .6" rgb2="0 0 0" width="100" height="100" />
        <texture builtin="flat" height="1278" mark="cross" markrgb="1 1 1" name="texgeom" random="0.01" rgb1="0.8 0.6 0.4" rgb2="0.8 0.6 0.4" type="cube" width="127" />
        <texture builtin="checker" height="100" name="texplane" rgb1="0 0 0" rgb2="0.8 0.8 0.8" type="2d" width="100" />
        <material name="MatPlane" reflectance="0.5" shininess="1" specular="1" texrepeat="60 60" texture="texplane" />
        <material name="geom" texture="texgeom" texuniform="true" />
    </asset>

  <sensor>
    <force site="torso_thigh_site" name="torso_thigh_sensor" />
    <force site="thigh_leg_site" name="thigh_leg_sensor" />
    <force site="leg_foot_site" name="leg_foot_sensor" />
    <force site="torso_thigh_left_site" name="torso_thigh_left_sensor" />
    <force site="thigh_leg_left_site" name="thigh_leg_left_sensor" />
    <force site="leg_foot_left_site" name="leg_foot_left_sensor" />
  </sensor>
</mujoco>